<?xml version="1.0"?>
<robot name="my_bot">

    <material name="yellow_light">
        <color rgba="1.0 1.0 0.0 0.7"/>
    </material>

    <material name ='wooden'>
        <color rgba='0.76 0.60 0.024 1'/>
    </material>

    <material name ='black'>
        <color rgba='0.0 0.0 0.0 1'/>
    </material>

    <link name="base_link">
    </link>

    <link name="base_footprint">
    </link>
    
    <joint name="footprint_joint" type="fixed">
        <parent link="base_link"/>
        <child link="base_footprint"/>
        <origin xyz="0 0 0" rpy="0 0 0"/>
    </joint>

    <!-- B O D Y -->
    <link name="chassis">
        <visual>
            <geometry>
                <box size="0.3 0.54 0.15"/>
            </geometry>
            <material name="wooden"/>
        </visual>

        <collision>
            <geometry>
                <box size="0.3 0.54 0.15"/>
            </geometry>
        </collision>

        <inertial>
            <mass value="0.1"/>
            <origin rpy="0 0 0" xyz="0 0 0"/>
            <inertia ixx=" 0.0026175000000000005" ixy="0" ixz="0" iyy="0.0009375" iyz="0" izz="0.004860000000000001"/>
        </inertial>

    </link>

    <joint name="base_link_joint" type="fixed">
        <origin rpy="0 0 1.57" xyz="0 0 0" />
        <parent link="base_link" />
        <child link="chassis" />
    </joint>

    <!-- Wheel Left -->
    <link name="left_wheel">
        <visual>
            <origin rpy="0 1.5707 0" xyz="0 0 0"/>
            <geometry>
                <cylinder length="0.06" radius="0.09"/>
            </geometry>
            <material name="yellow_light"/>
        </visual>

        <collision>
            <origin rpy="0 1.5707 0" xyz="0 0 0"/>
            <geometry>
                <cylinder length="0.06" radius="0.09"/>
            </geometry>
        </collision>

        <inertial>
            <origin rpy="0 1.5707 0" xyz="0 0 0"/>
            <mass value="0.1"/>
            <inertia ixx="0.00023250000000000004" ixy="0" ixz="0" iyy="0.00023250000000000004" iyz="0" izz="0.000405"/>
        </inertial>
    </link>
    
    <gazebo reference="left_wheel">
        <kp>100000000000000000000.0</kp>
        <kd>100000000000000000000.0</kd>
        <mu1>10</mu1>
        <mu2>10</mu2>
        <material>Gazebo/Black</material>
    </gazebo>

    <joint name="joint_left_wheel" type="continuous">
        <origin rpy="0 0 0" xyz="0.18 0 -0.025"/>
        <child link="left_wheel"/>
        <parent link="chassis"/>
        <axis rpy="0 0 0" xyz="1 0 0"/>
        <limit effort="10000" velocity="1000"/>
        <joint_properties damping="1.0" friction="1.0"/>
    </joint>

    <!-- Wheel Right -->
    <link name="right_wheel">
        <visual>
            <origin rpy="0 1.5707 0" xyz="0 0 0"/>
            <geometry>
                <cylinder length="0.06" radius="0.09"/>
            </geometry>
            <material name="yellow_light"/>
        </visual>

        <collision>
            <origin rpy="0 1.5707 0" xyz="0 0 0"/>
            <geometry>
                <cylinder length="0.06" radius="0.09"/>
            </geometry>
        </collision>

        <inertial>
            <origin rpy="0 1.5707 0" xyz="0 0 0"/>
            <mass value="0.1"/>
            <inertia ixx="0.00023250000000000004" ixy="0" ixz="0" iyy="0.00023250000000000004" iyz="0" izz="0.000405"/>
        </inertial>
    </link>

    <gazebo reference="right_wheel">
        <kp>100000000000000000000.0</kp>
        <kd>100000000000000000000.0</kd>
        <mu1>10</mu1>
        <mu2>10</mu2>
        <material>Gazebo/Black</material>
    </gazebo>

    <joint name="joint_right_wheel" type="continuous">
        <origin rpy="0 0 0" xyz="-0.18 0 -0.025"/>
        <child link="right_wheel"/>
        <parent link="chassis"/>
        <axis rpy="0 0 0" xyz="1 0 0"/>
        <limit effort="10000" velocity="1000"/>
        <joint_properties damping="1.0" friction="1.0"/>
    </joint>

    <!-- Caster Wheel Front -->
    <link name="front_yaw_link">
        <visual>
            <origin rpy="0 1.5707 1.5707" xyz="0 0 0"/>
            <geometry>
              <cylinder length="0.005" radius="0.04"/>
            </geometry>
            <material name="wooden"/>
        </visual>

        <collision>
            <origin rpy="0 1.5707 1.5707" xyz="0 0 0"/>
            <geometry>
                <cylinder length="0.005" radius="0.04"/>
            </geometry>
        </collision>

        <inertial>
            <origin rpy="0 1.5707 1.5707" xyz="0 0 0"/>
            <mass value="0.001"/>
            <inertia ixx="4.020833333333333e-07" ixy="0" ixz="0" iyy="4.020833333333333e-07" iyz="0" izz="8.000000000000001e-07"/>
        </inertial>
    </link>

    <joint name="front_yaw_joint" type="continuous">
        <origin rpy="0 0 0" xyz="0 -0.15 -0.075"/>
        <parent link="chassis" />
        <child link="front_yaw_link" />
        <axis xyz="0 0 1" />
        <limit effort="1000.0" velocity="100.0" />
        <dynamics damping="0.0" friction="0.1"/>
    </joint>

    <gazebo reference="front_yaw_link">
        <material>Gazebo/Purple</material>
    </gazebo>

    <link name="front_roll_link">
        <visual>
            <origin rpy="0 1.5707 1.5707" xyz="0 0 0"/>
            <geometry>
                <cylinder length="0.005" radius="0.04"/>
            </geometry>
            <material name="wooden"/>
        </visual>

        <collision>
            <origin rpy="0 1.5707 1.5707" xyz="0 0 0"/>
            <geometry>
                <cylinder length="0.005" radius="0.04"/>
            </geometry>
        </collision>

        <inertial>
            <origin rpy="0 1.5707 1.5707" xyz="0 0 0"/>
            <mass value="0.001"/>
            <inertia ixx="4.020833333333333e-07" ixy="0" ixz="0" iyy="4.020833333333333e-07" iyz="0" izz="8.000000000000001e-07"/>
        </inertial>
    </link>

    <joint name="front_roll_joint" type="continuous">
        <origin rpy="0 0 0" xyz="0 0 0" />
        <parent link="front_yaw_link" />
        <child link="front_roll_link" />
        <axis xyz="1 0 0" />
        <limit effort="1000.0" velocity="100.0" />
        <dynamics damping="0.0" friction="0.1"/>
    </joint>
        
    <gazebo reference="front_roll_link">
        <material>Gazebo/Purple</material>
    </gazebo>

    <link name="front_pitch_link">
        <visual>
            <origin rpy="0 1.5707 1.5707" xyz="0 0 0"/>
            <geometry>
                <sphere radius="0.04"/>
            </geometry>
            <material name="wooden"/>
        </visual>

        <collision>
            <origin rpy="0 1.5707 1.5707" xyz="0 0 0"/>
            <geometry>
                <sphere radius="0.04"/>
            </geometry>
        </collision>

        <inertial>
            <origin rpy="0 1.5707 1.5707" xyz="0 0 0"/>
            <mass value="0.001"/>
            <inertia ixx="6.4e-07" ixy="0" ixz="0" iyy="6.4e-07" iyz="0" izz="6.4e-07"/>
        </inertial>
    </link>

    <gazebo reference="front_pitch_link">
        <kp>100000000000000.0</kp>
        <kd>100000000000000.0</kd>
        <mu1>0.5</mu1>
        <mu2>0.5</mu2>
        <material>Gazebo/Purple</material>
    </gazebo>

    <joint name="front_pitch_joint" type="continuous">
        <origin rpy="0 0 0" xyz="0 0 0" />
        <parent link="front_roll_link" />
        <child link="front_pitch_link" />
        <axis xyz="0 1 0" />
        <limit effort="1000.0" velocity="100.0" />
        <dynamics damping="0.0" friction="0.1"/>
    </joint>

    <!-- Caster Wheel Back -->
    <link name="back_yaw_link">
        <visual>
            <origin rpy="0 1.5707 1.5707" xyz="0 0 0"/>
            <geometry>
              <cylinder length="0.005" radius="0.04"/>
            </geometry>
            <material name="wooden"/>
        </visual>

        <collision>
            <origin rpy="0 1.5707 1.5707" xyz="0 0 0"/>
            <geometry>
                <cylinder length="0.005" radius="0.04"/>
            </geometry>
        </collision>

        <inertial>
            <origin rpy="0 1.5707 1.5707" xyz="0 0 0"/>
            <mass value="0.001"/>
            <inertia ixx="4.020833333333333e-07" ixy="0" ixz="0" iyy="4.020833333333333e-07" iyz="0" izz="8.000000000000001e-07"/>
        </inertial>
    </link>

    <joint name="back_yaw_joint" type="continuous">
        <origin rpy="0 0 0" xyz="0 0.15 -0.075"/>
        <parent link="chassis" />
        <child link="back_yaw_link" />
        <axis xyz="0 0 1" />
        <limit effort="1000.0" velocity="100.0" />
        <dynamics damping="0.0" friction="0.1"/>
    </joint>

    <gazebo reference="back_yaw_link">
        <material>Gazebo/Purple</material>
    </gazebo>

    <link name="back_roll_link">
        <visual>
            <origin rpy="0 1.5707 1.5707" xyz="0 0 0"/>
            <geometry>
                <cylinder length="0.005" radius="0.04"/>
            </geometry>
            <material name="wooden"/>
        </visual>

        <collision>
            <origin rpy="0 1.5707 1.5707" xyz="0 0 0"/>
            <geometry>
                <cylinder length="0.005" radius="0.04"/>
            </geometry>
        </collision>

        <inertial>
            <origin rpy="0 1.5707 1.5707" xyz="0 0 0"/>
            <mass value="0.001"/>
            <inertia ixx="4.020833333333333e-07" ixy="0" ixz="0" iyy="4.020833333333333e-07" iyz="0" izz="8.000000000000001e-07"/>
        </inertial>
    </link>

    <joint name="back_roll_joint" type="continuous">
        <origin rpy="0 0 0" xyz="0 0 0"/>
        <parent link="back_yaw_link"/>
        <child link="back_roll_link"/>
        <axis xyz="1 0 0" />
        <limit effort="1000.0" velocity="100.0" />
        <dynamics damping="0.0" friction="0.1"/>
    </joint>
        
    <gazebo reference="back_roll_link">
        <material>Gazebo/Purple</material>
    </gazebo>

    <link name="back_pitch_link">
        <visual>
            <origin rpy="0 1.5707 1.5707" xyz="0 0 0"/>
            <geometry>
                <sphere radius="0.04"/>
            </geometry>
            <material name="wooden"/>
        </visual>

        <collision>
            <origin rpy="0 1.5707 1.5707" xyz="0 0 0"/>
            <geometry>
                <sphere radius="0.04"/>
            </geometry>
        </collision>

        <inertial>
            <origin rpy="0 1.5707 1.5707" xyz="0 0 0"/>
            <mass value="0.001"/>
            <inertia ixx="6.4e-07" ixy="0" ixz="0" iyy="6.4e-07" iyz="0" izz="6.4e-07"/>
        </inertial>
    </link>

    <gazebo reference="back_pitch_link">
        <kp>100000000000000.0</kp>
        <kd>100000000000000.0</kd>
        <mu1>0.5</mu1>
        <mu2>0.5</mu2>
        <material>Gazebo/Purple</material>
    </gazebo>

    <joint name="back_pitch_joint" type="continuous">
        <origin rpy="0 0 0" xyz="0 0 0" />
        <parent link="back_roll_link" />
        <child link="back_pitch_link" />
        <axis xyz="0 1 0" />
        <limit effort="1000.0" velocity="100.0" />
        <dynamics damping="0.0" friction="0.1"/>
    </joint>

   <joint name="camera_joint" type="fixed">
        <parent link="chassis"/>
        <child link="camera_link"/>
        <origin xyz="0 -0.27 0.08" rpy="0 0.22 -1.57"/>
    </joint>

    <link name="camera_link">
        <visual>
            <geometry>
                <box size="0.010 0.03 0.03"/>
            </geometry>
            <material name="black"/>
        </visual>
        <visual>
            <origin xyz="0 0 -0.05"/>
            <geometry>
                <cylinder radius="0.002" length="0.1"/>
            </geometry>
            <material name="black"/>
        </visual>
    </link>

    <!--ULTRA SONIC-->
    <link name="base_sonar_front">
        <collision>
            <origin xyz="0 0 0" rpy="0 0 0"/>
            <geometry>
                <box size="0.01 0.01 0.01"/>
            </geometry>
        </collision>
        <visual>
            <origin xyz="0 0 0" rpy="0 0 0"/>
            <geometry>
                <box size="0.01 0.01 0.01"/>
            </geometry>
        </visual>
        <inertial>
            <mass value="1e-5" />
            <origin xyz="0 0 0" rpy="0 0 0"/>
            <inertia ixx="1e-6" ixy="0" ixz="0" iyy="1e-6" iyz="0" izz="1e-6" />
        </inertial>
    </link>
    <joint name="sonar_front_joint" type="fixed">
        <axis xyz="0 1 0" />
        <origin rpy="0 0 -1.57" xyz="0.0 -0.27 0" />
        <parent link="chassis"/>
        <child link="base_sonar_front"/>
    </joint>

    <gazebo reference="base_sonar_front">
        <sensor name="ultrasonic_1" type="ray">
            <pose>0 0 0 0 0 0</pose>
            <visualize>true</visualize>
            <update_rate>20</update_rate>
            <ray>
                <scan>
                    <horizontal>
                        <samples>5</samples>
                        <resolution>1.000000</resolution>
                        <min_angle>-0.12</min_angle>
                        <max_angle>0.12</max_angle>
                    </horizontal>
                    <vertical>
                        <samples>5</samples>
                        <resolution>1.000000</resolution>
                        <min_angle>-0.01</min_angle>
                        <max_angle>0.01</max_angle>
                    </vertical>
                </scan>
                <range>
                    <min>0.02</min>
                    <max>4</max>
                    <resolution>0.01</resolution>
                </range>
                <noise>
                    <type>gaussian</type>
                    <mean>0.0</mean>
                    <stddev>0.01</stddev>
                </noise>
            </ray>
            <plugin name="ultrasonic_sensor_1" filename="libgazebo_ros_ray_sensor.so">
                <ros>
                    <remapping>~/out:=ultrasonic_sensor</remapping>
                </ros>
                <output_type>sensor_msgs/Range</output_type>
                <radiation_type>ultrasound</radiation_type>
                <frame_name>base_sonar_front</frame_name>
            </plugin>
        </sensor>  
    </gazebo>

    <!-- PLUGINS -->
    <!-- JOINT PUBLISHER -->
    <gazebo>
        <plugin name="bot_joint_state" filename="libgazebo_ros_joint_state_publisher.so">
            <ros>
                <remapping>~/out:=joint_states</remapping>
            </ros>
            <update_rate>30</update_rate>

            <joint_name>joint_left_wheel</joint_name>
            <joint_name>joint_right_wheel</joint_name>
            <joint_name>front_yaw_joint</joint_name>
            <joint_name>back_yaw_joint</joint_name>
            <joint_name>front_roll_joint</joint_name>             
            <joint_name>back_roll_joint</joint_name>
            <joint_name>front_pitch_joint</joint_name>
            <joint_name>back_pitch_joint</joint_name>
            <joint_name>sonar_front_joint</joint_name>
            <joint_name>camera_joint</joint_name>
        </plugin>
    </gazebo>

    <gazebo reference="camera_link">
        <material>Gazebo/Black</material>

        <sensor name="camera_rgb" type="camera">
            <pose> 0 0 0 0 0 0 </pose>
            <visualize>true</visualize>
            <update_rate>10</update_rate>
            <camera>
                <horizontal_fov>1.089</horizontal_fov>
                <image>
                    <format>R8G8B8</format>
                    <width>640</width>
                    <height>480</height>
                </image>
                <clip>
                    <near>0.05</near>
                    <far>8.0</far>
                </clip>
            </camera>
            <plugin name="camera_rgb_controller" filename="libgazebo_ros_camera.so">
                <frame_name>camera_link_optical</frame_name>
            </plugin>
        </sensor>
    </gazebo>

    <gazebo>
        <plugin name="differential_drive_controller" filename="libgazebo_ros_diff_drive.so">

            <!-- Wheel Information -->
            <update_rate>30</update_rate>
            <left_joint>joint_left_wheel</left_joint>
            <right_joint>joint_right_wheel</right_joint>
            <wheel_separation>0.36</wheel_separation>
            <wheel_diameter>0.18</wheel_diameter>
            <!-- Limits -->
            <max_wheel_torque>1.0</max_wheel_torque>
            <max_wheel_acceleration>1.0</max_wheel_acceleration>
            <!-- Output -->
            <command_topic>cmd_vel</command_topic>
            <publish_odom>true</publish_odom>
            <publish_odom_tf>true</publish_odom_tf>
            <odometry_frame>odom</odometry_frame>
            <robot_base_frame>base_link</robot_base_frame>
            <publish_wheel_tf>true</publish_wheel_tf>
        </plugin>
    </gazebo>

</robot>
